Workbook

Sheet 获奖信息
A1: 序号 | B1: 时间 | C1: 科室 | D1: 获奖途径 | E1: 所获奖项分类 | F1: 所获奖项级别 | G1: 奖项名称 | H1: 符合“首次”奖励 | I1: 同课题总积分 | J1: 获奖人姓名 | K1: 获奖人工号 | L1: 备注 | M1: 占比计算 | N1: 总额 | O1: 终值 | P1: 列1 | AA1: 总装科 | AB1: 外部获奖
A2: 1 | B2: 45741 | C2: 设备动力科 | D2: 内部获奖 | E2: 工厂级QC发表获奖 | F2: 一等奖 | H2: 否 | I2: {=IF(OR(D2="", E2="", F2=""), "", INDEX(积分标准!$D$2:$D$100, MATCH(1, (积分标准!$A$2:$A$100=D2) * (积分标准!$B$2:$B$100=E2) * (积分标准!$C$2:$C$100=F2), 0)) + IF(H2="是", 0.5, 0))} -> 2.5 | J2: 王瑞林 | K2: 8699083 | M2: 280 | N2: 2000 | O2: =M2/N2*I2 -> 0.35 | AA2: 冲焊科
A3: 2 | B3: 45741 | C3: 设备动力科 | D3: 内部获奖 | E3: 工厂级QC发表获奖 | F3: 一等奖 | H3: 否 | I3: {=IF(OR(D3="", E3="", F3=""), "", INDEX(积分标准!$D$2:$D$100, MATCH(1, (积分标准!$A$2:$A$100=D3) * (积分标准!$B$2:$B$100=E3) * (积分标准!$C$2:$C$100=F3), 0)) + IF(H3="是", 0.5, 0))} -> 2.5 | J3: 师铮 | K3: 8676014 | M3: 280 | N3: 2000 | O3: =M3/N3*I3 -> 0.35 | AA3: 涂树科
A4: 3 | B4: 45741 | C4: 设备动力科 | D4: 内部获奖 | E4: 工厂级QC发表获奖 | F4: 一等奖 | H4: 否 | I4: {=IF(OR(D4="", E4="", F4=""), "", INDEX(积分标准!$D$2:$D$100, MATCH(1, (积分标准!$A$2:$A$100=D4) * (积分标准!$B$2:$B$100=E4) * (积分标准!$C$2:$C$100=F4), 0)) + IF(H4="是", 0.5, 0))} -> 2.5 | J4: 唐小光 | K4: 8673997 | M4: 280 | N4: 2000 | O4: =M4/N4*I4 -> 0.35 | AA4: 工业工程科
A5: 4 | B5: 45741 | C5: 设备动力科 | D5: 内部获奖 | E5: 工厂级QC发表获奖 | F5: 一等奖 | H5: 否 | I5: {=IF(OR(D5="", E5="", F5=""), "", INDEX(积分标准!$D$2:$D$100, MATCH(1, (积分标准!$A$2:$A$100=D5) * (积分标准!$B$2:$B$100=E5) * (积分标准!$C$2:$C$100=F5), 0)) + IF(H5="是", 0.5, 0))} -> 2.5 | J5: 于勇 | K5: 8680311 | M5: 280 | N5: 2000 | O5: =M5/N5*I5 -> 0.35 | AA5: 品质保证科
A6: 5 | B6: 45741 | C6: 设备动力科 | D6: 内部获奖 | E6: 工厂级QC发表获奖 | F6: 一等奖 | H6: 否 | I6: {=IF(OR(D6="", E6="", F6=""), "", INDEX(积分标准!$D$2:$D$100, MATCH(1, (积分标准!$A$2:$A$100=D6) * (积分标准!$B$2:$B$100=E6) * (积分标准!$C$2:$C$100=F6), 0)) + IF(H6="是", 0.5, 0))} -> 2.5 | J6: 田晓明 | K6: 8681583 | M6: 280 | N6: 2000 | O6: =M6/N6*I6 -> 0.35 | AA6: 设备动力科
A7: 6 | B7: 45741 | C7: 工业工程科 | D7: 内部获奖 | E7: 工厂级QC发表获奖 | F7: 一等奖 | H7: 否 | I7: {=IF(OR(D7="", E7="", F7=""), "", INDEX(积分标准!$D$2:$D$100, MATCH(1, (积分标准!$A$2:$A$100=D7) * (积分标准!$B$2:$B$100=E7) * (积分标准!$C$2:$C$100=F7), 0)) + IF(H7="是", 0.5, 0))} -> 2.5 | J7: 王晓冬 | K7: 8680291 | M7: 200 | N7: 2000 | O7: =M7/N7*I7 -> 0.25 | AA7: 技术科
A8: 7 | B8: 45741 | C8: 工业工程科 | D8: 内部获奖 | E8: 工厂级QC发表获奖 | F8: 一等奖 | H8: 否 | I8: {=IF(OR(D8="", E8="", F8=""), "", INDEX(积分标准!$D$2:$D$100, MATCH(1, (积分标准!$A$2:$A$100=D8) * (积分标准!$B$2:$B$100=E8) * (积分标准!$C$2:$C$100=F8), 0)) + IF(H8="是", 0.5, 0))} -> 2.5 | J8: 李涛 | K8: 8682097 | M8: 200 | N8: 2000 | O8: =M8/N8*I8 -> 0.25 | AA8: 生产管理科
A9: 8 | B9: 45741 | C9: 工业工程科 | D9: 内部获奖 | E9: 工厂级QC发表获奖 | F9: 一等奖 | H9: 否 | I9: {=IF(OR(D9="", E9="", F9=""), "", INDEX(积分标准!$D$2:$D$100, MATCH(1, (积分标准!$A$2:$A$100=D9) * (积分标准!$B$2:$B$100=E9) * (积分标准!$C$2:$C$100=F9), 0)) + IF(H9="是", 0.5, 0))} -> 2.5 | J9: 王冠 | K9: 8698876 | M9: 200 | N9: 2000 | O9: =M9/N9*I9 -> 0.25 | AA9: 综合管理科
A10: 9 | B10: 45741 | C10: 生产管理科 | D10: 内部获奖 | E10: 工厂级QC发表获奖 | F10: 二等奖 | H10: 否 | I10: {=IF(OR(D10="", E10="", F10=""), "", INDEX(积分标准!$D$2:$D$100, MATCH(1, (积分标准!$A$2:$A$100=D10) * (积分标准!$B$2:$B$100=E10) * (积分标准!$C$2:$C$100=F10), 0)) + IF(H10="是", 0.5, 0))} -> 2 | J10: 鲁家嫡 | K10: 8683980 | M10: 250 | N10: 1500 | O10: =M10/N10*I10 -> 0.33333333 | AA10: 安技环保科
A11: 10 | B11: 45741 | C11: 生产管理科 | D11: 内部获奖 | E11: 工厂级QC发表获奖 | F11: 二等奖 | H11: 否 | I11: {=IF(OR(D11="", E11="", F11=""), "", INDEX(积分标准!$D$2:$D$100, MATCH(1, (积分标准!$A$2:$A$100=D11) * (积分标准!$B$2:$B$100=E11) * (积分标准!$C$2:$C$100=F11), 0)) + IF(H11="是", 0.5, 0))} -> 2 | J11: 于文书 | K11: 8683979 | M11: 250 | N11: 1500 | O11: =M11/N11*I11 -> 0.33333333 | AA11: 大连财务科
A12: 11 | B12: 45741 | C12: 生产管理科 | D12: 内部获奖 | E12: 工厂级QC发表获奖 | F12: 二等奖 | H12: 否 | I12: {=IF(OR(D12="", E12="", F12=""), "", INDEX(积分标准!$D$2:$D$100, MATCH(1, (积分标准!$A$2:$A$100=D12) * (积分标准!$B$2:$B$100=E12) * (积分标准!$C$2:$C$100=F12), 0)) + IF(H12="是", 0.5, 0))} -> 2 | J12: 赵晓明 | K12: 8612473 | M12: 250 | N12: 1500 | O12: =M12/N12*I12 -> 0.33333333 | AA12: 党群工作室
A13: 12 | B13: 45715 | C13: 生产管理科 | D13: 内部获奖 | E13: 工厂级QC发表获奖 | F13: 二等奖 | H13: 否 | I13: {=IF(OR(D13="", E13="", F13=""), "", INDEX(积分标准!$D$2:$D$100, MATCH(1, (积分标准!$A$2:$A$100=D13) * (积分标准!$B$2:$B$100=E13) * (积分标准!$C$2:$C$100=F13), 0)) + IF(H13="是", 0.5, 0))} -> 2 | J13: 祝益盛 | K13: 8675741 | M13: 250 | N13: 1500 | O13: =M13/N13*I13 -> 0.33333333 | AA13: 大连部品科
A14: 13 | B14: 45715 | C14: 生产管理科 | D14: 内部获奖 | E14: 工厂级QC发表获奖 | F14: 二等奖 | H14: 否 | I14: {=IF(OR(D14="", E14="", F14=""), "", INDEX(积分标准!$D$2:$D$100, MATCH(1, (积分标准!$A$2:$A$100=D14) * (积分标准!$B$2:$B$100=E14) * (积分标准!$C$2:$C$100=F14), 0)) + IF(H14="是", 0.5, 0))} -> 2 | J14: 王洋 | K14: 8684029 | M14: 250 | N14: 1500 | O14: =M14/N14*I14 -> 0.33333333
A15: 14 | B15: 45715 | C15: 生产管理科 | D15: 内部获奖 | E15: 工厂级QC发表获奖 | F15: 二等奖 | H15: 否 | I15: {=IF(OR(D15="", E15="", F15=""), "", INDEX(积分标准!$D$2:$D$100, MATCH(1, (积分标准!$A$2:$A$100=D15) * (积分标准!$B$2:$B$100=E15) * (积分标准!$C$2:$C$100=F15), 0)) + IF(H15="是", 0.5, 0))} -> 2 | J15: 迟健鹏 | K15: 8683718 | M15: 250 | N15: 1500 | O15: =M15/N15*I15 -> 0.33333333
A16: 15 | B16: 45715 | C16: 涂树科 | D16: 内部获奖 | E16: 工厂级QC发表获奖 | F16: 二等奖 | H16: 否 | I16: {=IF(OR(D16="", E16="", F16=""), "", INDEX(积分标准!$D$2:$D$100, MATCH(1, (积分标准!$A$2:$A$100=D16) * (积分标准!$B$2:$B$100=E16) * (积分标准!$C$2:$C$100=F16), 0)) + IF(H16="是", 0.5, 0))} -> 2 | J16: 刘建勋 | K16: 8681239 | M16: 500 | N16: 1500 | O16: =M16/N16*I16 -> 0.66666667
A17: 16 | B17: 45715 | C17: 涂树科 | D17: 内部获奖 | E17: 工厂级QC发表获奖 | F17: 二等奖 | H17: 否 | I17: {=IF(OR(D17="", E17="", F17=""), "", INDEX(积分标准!$D$2:$D$100, MATCH(1, (积分标准!$A$2:$A$100=D17) * (积分标准!$B$2:$B$100=E17) * (积分标准!$C$2:$C$100=F17), 0)) + IF(H17="是", 0.5, 0))} -> 2 | J17: 刘敬彬 | K17: 8612665 | M17: 500 | N17: 1500 | O17: =M17/N17*I17 -> 0.66666667
A18: 17 | B18: 45715 | C18: 设备动力科 | D18: 内部获奖 | E18: 工厂级QC发表获奖 | F18: 二等奖 | H18: 否 | I18: {=IF(OR(D18="", E18="", F18=""), "", INDEX(积分标准!$D$2:$D$100, MATCH(1, (积分标准!$A$2:$A$100=D18) * (积分标准!$B$2:$B$100=E18) * (积分标准!$C$2:$C$100=F18), 0)) + IF(H18="是", 0.5, 0))} -> 2 | J18: 于洪军 | K18: 8685694 | M18: 500 | N18: 1500 | O18: =M18/N18*I18 -> 0.66666667
A19: 18 | B19: 45715 | C19: 冲焊科 | D19: 内部获奖 | E19: 工厂级QC发表获奖 | F19: 三等奖 | H19: 否 | I19: {=IF(OR(D19="", E19="", F19=""), "", INDEX(积分标准!$D$2:$D$100, MATCH(1, (积分标准!$A$2:$A$100=D19) * (积分标准!$B$2:$B$100=E19) * (积分标准!$C$2:$C$100=F19), 0)) + IF(H19="是", 0.5, 0))} -> 1.5 | J19: 时守毅 | K19: 8676581 | M19: 400 | N19: 1000 | O19: =M19/N19*I19 -> 0.6
A20: 19 | B20: 45715 | C20: 冲焊科 | D20: 内部获奖 | E20: 工厂级QC发表获奖 | F20: 三等奖 | H20: 否 | I20: {=IF(OR(D20="", E20="", F20=""), "", INDEX(积分标准!$D$2:$D$100, MATCH(1, (积分标准!$A$2:$A$100=D20) * (积分标准!$B$2:$B$100=E20) * (积分标准!$C$2:$C$100=F20), 0)) + IF(H20="是", 0.5, 0))} -> 1.5 | J20: 宋畅 | K20: 8676591 | M20: 400 | N20: 1000 | O20: =M20/N20*I20 -> 0.6
A21: 20 | B21: 45715 | C21: 冲焊科 | D21: 内部获奖 | E21: 工厂级QC发表获奖 | F21: 三等奖 | H21: 否 | I21: {=IF(OR(D21="", E21="", F21=""), "", INDEX(积分标准!$D$2:$D$100, MATCH(1, (积分标准!$A$2:$A$100=D21) * (积分标准!$B$2:$B$100=E21) * (积分标准!$C$2:$C$100=F21), 0)) + IF(H21="是", 0.5, 0))} -> 1.5 | J21: 杨康 | K21: 8700494 | M21: 200 | N21: 1000 | O21: =M21/N21*I21 -> 0.3
A22: 21 | B22: 45715 | C22: 品质保证科 | D22: 内部获奖 | E22: 工厂级QC发表获奖 | F22: 三等奖 | H22: 否 | I22: {=IF(OR(D22="", E22="", F22=""), "", INDEX(积分标准!$D$2:$D$100, MATCH(1, (积分标准!$A$2:$A$100=D22) * (积分标准!$B$2:$B$100=E22) * (积分标准!$C$2:$C$100=F22), 0)) + IF(H22="是", 0.5, 0))} -> 1.5 | J22: 张洪宇 | K22: 8680051 | M22: 200 | N22: 1000 | O22: =M22/N22*I22 -> 0.3
A23: 22 | B23: 45715 | C23: 品质保证科 | D23: 内部获奖 | E23: 工厂级QC发表获奖 | F23: 三等奖 | H23: 否 | I23: {=IF(OR(D23="", E23="", F23=""), "", INDEX(积分标准!$D$2:$D$100, MATCH(1, (积分标准!$A$2:$A$100=D23) * (积分标准!$B$2:$B$100=E23) * (积分标准!$C$2:$C$100=F23), 0)) + IF(H23="是", 0.5, 0))} -> 1.5 | J23: 于慧缘 | K23: 8673998 | M23: 200 | N23: 1000 | O23: =M23/N23*I23 -> 0.3
A24: 23 | B24: 45715 | C24: 品质保证科 | D24: 内部获奖 | E24: 工厂级QC发表获奖 | F24: 三等奖 | H24: 否 | I24: {=IF(OR(D24="", E24="", F24=""), "", INDEX(积分标准!$D$2:$D$100, MATCH(1, (积分标准!$A$2:$A$100=D24) * (积分标准!$B$2:$B$100=E24) * (积分标准!$C$2:$C$100=F24), 0)) + IF(H24="是", 0.5, 0))} -> 1.5 | J24: 刘鹏 | K24: 8685711 | M24: 200 | N24: 1000 | O24: =M24/N24*I24 -> 0.3
A25: 24 | B25: 45715 | C25: 品质保证科 | D25: 内部获奖 | E25: 工厂级QC发表获奖 | F25: 三等奖 | H25: 否 | I25: {=IF(OR(D25="", E25="", F25=""), "", INDEX(积分标准!$D$2:$D$100, MATCH(1, (积分标准!$A$2:$A$100=D25) * (积分标准!$B$2:$B$100=E25) * (积分标准!$C$2:$C$100=F25), 0)) + IF(H25="是", 0.5, 0))} -> 1.5 | J25: 李春扬 | K25: 8674452 | M25: 200 | N25: 1000 | O25: =M25/N25*I25 -> 0.3
... A31: 30 | B31: 45715 | C31: 总装科 | D31: 内部获奖 | E31: 工厂级QC发表获奖 | F31: 三等奖 | H31: 否 | I31: {=IF(OR(D31="", E31="", F31=""), "", INDEX(积分标准!$D$2:$D$100, MATCH(1, (积分标准!$A$2:$A$100=D31) * (积分标准!$B$2:$B$100=E31) * (积分标准!$C$2:$C$100=F31), 0)) + IF(H31="是", 0.5, 0))} -> 1.5 | J31: 李闯 | K31: 8683084 | M31: 50 | N31: 1000 | O31: =M31/N31*I31 -> 0.075
A32: 31 | B32: 45720 | C32: 总装科 | D32: 内部获奖 | E32: 工厂级QC发表获奖 | F32: 一等奖 | H32: 否 | I32: {=IF(OR(D32="", E32="", F32=""), "", INDEX(积分标准!$D$2:$D$100, MATCH(1, (积分标准!$A$2:$A$100=D32) * (积分标准!$B$2:$B$100=E32) * (积分标准!$C$2:$C$100=F32), 0)) + IF(H32="是", 0.5, 0))} -> 2.5 | J32: 汲浩铭 | K32: 8674056 | L32: 数字化发表会 | M32: 600 | N32: 600 | O32: =M32/N32*I32 -> 2.5
A33: 32 | B33: 45720 | C33: 品质保证科 | D33: 内部获奖 | E33: 工厂级QC发表获奖 | F33: 二等奖 | H33: 是 | I33: {=IF(OR(D33="", E33="", F33=""), "", INDEX(积分标准!$D$2:$D$100, MATCH(1, (积分标准!$A$2:$A$100=D33) * (积分标准!$B$2:$B$100=E33) * (积分标准!$C$2:$C$100=F33), 0)) + IF(H33="是", 0.5, 0))} -> 2.5 | J33: 于慧缘 | K33: 8673998 | L33: 数字化发表会 | M33: 400 | N33: 400 | O33: =M33/N33*I33 -> 2.5 | P33: 首次主担数字化课题
A34: 33 | B34: 45720 | C34: 品质保证科 | D34: 内部获奖 | E34: 工厂级QC发表获奖 | F34: 二等奖 | H34: 否 | I34: {=IF(OR(D34="", E34="", F34=""), "", INDEX(积分标准!$D$2:$D$100, MATCH(1, (积分标准!$A$2:$A$100=D34) * (积分标准!$B$2:$B$100=E34) * (积分标准!$C$2:$C$100=F34), 0)) + IF(H34="是", 0.5, 0))} -> 2 | J34: 殷丞君 | K34: 8722477 | L34: 数字化发表会 | M34: 400 | N34: 400 | O34: =M34/N34*I34 -> 2
A35: 34 | B35: 45720 | C35: 工业工程科 | D35: 内部获奖 | E35: 工厂级QC发表获奖 | F35: 三等奖 | H35: 否 | I35: {=IF(OR(D35="", E35="", F35=""), "", INDEX(积分标准!$D$2:$D$100, MATCH(1, (积分标准!$A$2:$A$100=D35) * (积分标准!$B$2:$B$100=E35) * (积分标准!$C$2:$C$100=F35), 0)) + IF(H35="是", 0.5, 0))} -> 1.5 | J35: 王晓冬 | K35: 8680291 | L35: 数字化发表会 | M35: 200 | N35: 200 | O35: =M35/N35*I35 -> 1.5
A36: 35 | B36: 45720 | C36: 大连财务科 | D36: 内部获奖 | E36: 工厂级QC发表获奖 | F36: 三等奖 | H36: 否 | I36: {=IF(OR(D36="", E36="", F36=""), "", INDEX(积分标准!$D$2:$D$100, MATCH(1, (积分标准!$A$2:$A$100=D36) * (积分标准!$B$2:$B$100=E36) * (积分标准!$C$2:$C$100=F36), 0)) + IF(H36="是", 0.5, 0))} -> 1.5 | J36: 纪舒沫 | K36: 8672926 | L36: 数字化发表会 | M36: 200 | N36: 200 | O36: =M36/N36*I36 -> 1.5
A37: 36 | B37: 45720 | C37: 冲焊科 | D37: 内部获奖 | E37: 工厂级QC发表获奖 | F37: 三等奖 | H37: 否 | I37: {=IF(OR(D37="", E37="", F37=""), "", INDEX(积分标准!$D$2:$D$100, MATCH(1, (积分标准!$A$2:$A$100=D37) * (积分标准!$B$2:$B$100=E37) * (积分标准!$C$2:$C$100=F37), 0)) + IF(H37="是", 0.5, 0))} -> 1.5 | J37: 宋畅 | K37: 8676591 | L37: 数字化发表会 | M37: 200 | N37: 200 | O37: =M37/N37*I37 -> 1.5
A38: 37 | B38: 45678 | C38: 设备动力科 | D38: 外部获奖 | E38: DFN级/市级奖项 | F38: 一等奖 | H38: 否 | I38: {=IF(OR(D38="", E38="", F38=""), "", INDEX(积分标准!$D$2:$D$100, MATCH(1, (积分标准!$A$2:$A$100=D38) * (积分标准!$B$2:$B$100=E38) * (积分标准!$C$2:$C$100=F38), 0)) + IF(H38="是", 0.5, 0))} -> 3 | J38: 王瑞林 | K38: 8699083 | L38: DFN数字化技能大赛 | M38: 1 | N38: 1 | O38: =M38/N38*I38 -> 3
A39: 38 | B39: 45658 | C39: 品质保证科 | D39: 外部获奖 | E39: DFN级/市级奖项 | F39: 三等奖 | H39: 否 | I39: {=IF(OR(D39="", E39="", F39=""), "", INDEX(积分标准!$D$2:$D$100, MATCH(1, (积分标准!$A$2:$A$100=D39) * (积分标准!$B$2:$B$100=E39) * (积分标准!$C$2:$C$100=F39), 0)) + IF(H39="是", 0.5, 0))} -> 1 | J39: 乔传泉 | K39: 8687986 | L39: 2024年优秀质量体系重点课题 | M39: 1 | N39: 1 | O39: =M39/N39*I39 -> 1
A40: 39 | B40: 45689 | C40: 安技环保科 | D40: 外部获奖 | E40: 全国级/DFG级奖项 | F40: 综合奖项 | H40: 否 | I40: {=IF(OR(D40="", E40="", F40=""), "", INDEX(积分标准!$D$2:$D$100, MATCH(1, (积分标准!$A$2:$A$100=D40) * (积分标准!$B$2:$B$100=E40) * (积分标准!$C$2:$C$100=F40), 0)) + IF(H40="是", 0.5, 0))} -> 3 | J40: 谢天文 | K40: 8696816 | L40: 2024年企业绿色低碳发展优秀案例 | M40: 1 | N40: 1 | O40: =M40/N40*I40 -> 3
A41: 40 | B41: 45748 | C41: 技术科 | D41: 外部获奖 | E41: 全国级/DFG级奖项 | F41: 二等奖 | H41: 否 | I41: {=IF(OR(D41="", E41="", F41=""), "", INDEX(积分标准!$D$2:$D$100, MATCH(1, (积分标准!$A$2:$A$100=D41) * (积分标准!$B$2:$B$100=E41) * (积分标准!$C$2:$C$100=F41), 0)) + IF(H41="是", 0.5, 0))} -> 4 | J41: 马骥 | K41: 8683930 | L41: 全国机械冶金建材行业职工技术创新成果 | M41: 1 | N41: 1 | O41: =M41/N41*I41 -> 4
A42: 41 | B42: 45748 | C42: 工业工程科 | D42: 外部获奖 | E42: 全国级/DFG级奖项 | F42: 三等奖 | H42: 否 | I42: {=IF(OR(D42="", E42="", F42=""), "", INDEX(积分标准!$D$2:$D$100, MATCH(1, (积分标准!$A$2:$A$100=D42) * (积分标准!$B$2:$B$100=E42) * (积分标准!$C$2:$C$100=F42), 0)) + IF(H42="是", 0.5, 0))} -> 3 | J42: 宋伟 | K42: 8680603 | L42: 全国机械冶金建材行业职工技术创新成果 | M42: 1 | N42: 1 | O42: =M42/N42*I42 -> 3
A43: 42 | B43: 45748 | C43: 设备动力科 | D43: 外部获奖 | E43: 全国级/DFG级奖项 | F43: 综合奖项 | H43: 否 | I43: {=IF(OR(D43="", E43="", F43=""), "", INDEX(积分标准!$D$2:$D$100, MATCH(1, (积分标准!$A$2:$A$100=D43) * (积分标准!$B$2:$B$100=E43) * (积分标准!$C$2:$C$100=F43), 0)) + IF(H43="是", 0.5, 0))} -> 3 | J43: 丁友贺 | K43: 8615446 | L43: 东风最佳实践课题获奖 | M43: 1 | N43: 1 | O43: =M43/N43*I43 -> 3
A44: 43 | B44: 45783 | C44: 工业工程科 | D44: 内部获奖 | E44: 数字化课题开发 | F44: 重点课题 | G44: 商品车是否订单车自动解析 | H44: 是 | I44: {=IF(OR(D44="", E44="", F44=""), "", INDEX(积分标准!$D$2:$D$100, MATCH(1, (积分标准!$A$2:$A$100=D44) * (积分标准!$B$2:$B$100=E44) * (积分标准!$C$2:$C$100=F44), 0)) + IF(H44="是", 0.5, 0))} -> 2.5 | J44: 宋伟 | K44: 8680603 | M44: 1 | N44: 1 | O44: =M44/N44*I44 -> 2.5
A45: 44 | B45: 45783 | C45: 涂树科 | D45: 内部获奖 | E45: 数字化课题开发 | F45: 普通课题 | G45: 科室单台成本动态管控可视化 | H45: 是 | I45: {=IF(OR(D45="", E45="", F45=""), "", INDEX(积分标准!$D$2:$D$100, MATCH(1, (积分标准!$A$2:$A$100=D45) * (积分标准!$B$2:$B$100=E45) * (积分标准!$C$2:$C$100=F45), 0)) + IF(H45="是", 0.5, 0))} -> 1.5 | J45: 纪明达 | K45: 8683064 | M45: 1 | N45: 1 | O45: =M45/N45*I45 -> 1.5
...

Sheet Sheet1

Sheet 人员信息
A1: 姓名 | B1: 工号 | C1: 部门 | D1: 科室
A2: 李道思 | B2: 8610486 | C2: 大连工厂
A3: 张培 | B3: 8684958 | C3: 大连工厂
A4: 戴岩 | B4: 8656578 | C4: 工务部
A5: 李伟 | B5: 8630960 | C5: 综合部
A6: 张劼 | B6: 8601498 | C6: 党群工作部 | D6: 党群工作室
A7: 踪祥 | B7: 8661958 | C7: 综合部 | D7: 综合管理科
A8: 胡鑫 | B8: 8613192 | C8: 工务部 | D8: 生产管理科
A9: 韩伯杰 | B9: 8620551 | C9: 制造部 | D9: 涂树科
A10: 李培勇 | B10: 8614905 | C10: 制造部 | D10: 总装科
A11: 郭月磊 | B11: 8672924 | C11: 制造部 | D11: 冲焊科
A12: 刘东 | B12: 8630949 | C12: 工务部 | D12: 品质保证科
A13: 杨传辉 | B13: 8672927 | C13: 工务部 | D13: 设备动力科
A14: 许铮 | B14: 8686062 | C14: 工务部 | D14: 工业工程科
A15: 苏驰 | B15: 8678830 | C15: 工务部 | D15: 技术科
A16: 张彪 | B16: 8620610 | C16: 工务部 | D16: 技术科
A17: 王静芳 | B17: 8686809 | C17: 综合部 | D17: 安技环保科
... A30: 于津 | B30: 8696248 | C30: 工务部 | D30: 技术科
A31: 张哲 | B31: 8695568 | C31: 工务部 | D31: 技术科
A32: 王元 | B32: 8696518 | C32: 工务部 | D32: 技术科
A33: 吴广超 | B33: 8687765 | C33: 工务部 | D33: 工业工程科
A34: 杨红波 | B34: 8620291 | C34: 工务部 | D34: 生产管理科
A35: 郭艳波 | B35: 8680611 | C35: 工务部 | D35: 生产管理科
A36: 薛晶晶 | B36: 8683691 | C36: 工务部 | D36: 工业工程科
A37: 许红科 | B37: 8683928 | C37: 工务部 | D37: 品质保证科
A38: 李凤文 | B38: 8672918 | C38: 工务部 | D38: 设备动力科
A39: 邹斌 | B39: 8672818 | C39: 党群工作部 | D39: 党群工作室
A40: 师铮 | B40: 8676014 | C40: 工务部 | D40: 设备动力科
A41: 杨艳宝 | B41: 8675885 | C41: 工务部 | D41: 设备动力科
A42: 刘昇 | B42: 8613261 | C42: 工务部 | D42: 设备动力科
A43: 宋伟 | B43: 8680603 | C43: 工务部 | D43: 工业工程科
A44: 王磊 | B44: 8693576 | C44: 工务部 | D44: 设备动力科
A45: 何德财 | B45: 8683690 | C45: 工务部 | D45: 品质保证科
A46: 乔传泉 | B46: 8687986 | C46: 工务部 | D46: 品质保证科
A47: 王波 | B47: 8692280 | C47: 工务部 | D47: 技术科
A48: 李东坪 | B48: 8694998 | C48: 工务部 | D48: 设备动力科
A49: 孙承帅 | B49: 8694963 | C49: 工务部 | D49: 工业工程科
A50: 刘炜华 | B50: 8698965 | C50: 工务部 | D50: 设备动力科
A51: 王冠 | B51: 8698876 | C51: 工务部 | D51: 工业工程科
A52: 王瑞林 | B52: 8699083 | C52: 工务部 | D52: 设备动力科
...

Sheet DataDetails
A1: Number | B1: Time | C1: Section | D1: Channel | E1: Category | F1: Level | G1: Award Name | H1: First-time | I1: Total Points | J1: Name | K1: Employee ID | L1: Remarks | M1: Proportion Calculation | N1: Total Amount | O1: Final Value
A2: =获奖信息!A2 -> 1 | B2: =获奖信息!B2 -> 45741 | C2: =获奖信息!C2 -> 设备动力科 | D2: =获奖信息!D2 -> 内部获奖 | E2: =获奖信息!E2 -> 工厂级QC发表获奖 | F2: =获奖信息!F2 -> 一等奖 | G2: =获奖信息!G2 -> 0 | H2: =获奖信息!H2 -> 否 | ... O2: =获奖信息!O2 -> 0.35
A3: =获奖信息!A3 -> 2 | B3: =获奖信息!B3 -> 45741 | C3: =获奖信息!C3 -> 设备动力科 | D3: =获奖信息!D3 -> 内部获奖 | E3: =获奖信息!E3 -> 工厂级QC发表获奖 | F3: =获奖信息!F3 -> 一等奖 | G3: =获奖信息!G3 -> 0 | H3: =获奖信息!H3 -> 否 | ... O3: =获奖信息!O3 -> 0.35
A4: =获奖信息!A4 -> 3 | B4: =获奖信息!B4 -> 45741 | C4: =获奖信息!C4 -> 设备动力科 | D4: =获奖信息!D4 -> 内部获奖 | E4: =获奖信息!E4 -> 工厂级QC发表获奖 | F4: =获奖信息!F4 -> 一等奖 | G4: =获奖信息!G4 -> 0 | H4: =获奖信息!H4 -> 否 | ... O4: =获奖信息!O4 -> 0.35
A5: =获奖信息!A5 -> 4 | B5: =获奖信息!B5 -> 45741 | C5: =获奖信息!C5 -> 设备动力科 | D5: =获奖信息!D5 -> 内部获奖 | E5: =获奖信息!E5 -> 工厂级QC发表获奖 | F5: =获奖信息!F5 -> 一等奖 | G5: =获奖信息!G5 -> 0 | H5: =获奖信息!H5 -> 否 | ... O5: =获奖信息!O5 -> 0.35
A6: =获奖信息!A6 -> 5 | B6: =获奖信息!B6 -> 45741 | C6: =获奖信息!C6 -> 设备动力科 | D6: =获奖信息!D6 -> 内部获奖 | E6: =获奖信息!E6 -> 工厂级QC发表获奖 | F6: =获奖信息!F6 -> 一等奖 | G6: =获奖信息!G6 -> 0 | H6: =获奖信息!H6 -> 否 | ... O6: =获奖信息!O6 -> 0.35
A7: =获奖信息!A7 -> 6 | B7: =获奖信息!B7 -> 45741 | C7: =获奖信息!C7 -> 工业工程科 | D7: =获奖信息!D7 -> 内部获奖 | E7: =获奖信息!E7 -> 工厂级QC发表获奖 | F7: =获奖信息!F7 -> 一等奖 | G7: =获奖信息!G7 -> 0 | H7: =获奖信息!H7 -> 否 | ... O7: =获奖信息!O7 -> 0.25
A8: =获奖信息!A8 -> 7 | B8: =获奖信息!B8 -> 45741 | C8: =获奖信息!C8 -> 工业工程科 | D8: =获奖信息!D8 -> 内部获奖 | E8: =获奖信息!E8 -> 工厂级QC发表获奖 | F8: =获奖信息!F8 -> 一等奖 | G8: =获奖信息!G8 -> 0 | H8: =获奖信息!H8 -> 否 | ... O8: =获奖信息!O8 -> 0.25
A9: =获奖信息!A9 -> 8 | B9: =获奖信息!B9 -> 45741 | C9: =获奖信息!C9 -> 工业工程科 | D9: =获奖信息!D9 -> 内部获奖 | E9: =获奖信息!E9 -> 工厂级QC发表获奖 | F9: =获奖信息!F9 -> 一等奖 | G9: =获奖信息!G9 -> 0 | H9: =获奖信息!H9 -> 否 | ... O9: =获奖信息!O9 -> 0.25
A10: =获奖信息!A10 -> 9 | B10: =获奖信息!B10 -> 45741 | C10: =获奖信息!C10 -> 生产管理科 | D10: =获奖信息!D10 -> 内部获奖 | E10: =获奖信息!E10 -> 工厂级QC发表获奖 | F10: =获奖信息!F10 -> 二等奖 | G10: =获奖信息!G10 -> 0 | H10: =获奖信息!H10 -> 否 | ... O10: =获奖信息!O10 -> 0.33333333
A11: =获奖信息!A11 -> 10 | B11: =获奖信息!B11 -> 45741 | C11: =获奖信息!C11 -> 生产管理科 | D11: =获奖信息!D11 -> 内部获奖 | E11: =获奖信息!E11 -> 工厂级QC发表获奖 | F11: =获奖信息!F11 -> 二等奖 | G11: =获奖信息!G11 -> 0 | H11: =获奖信息!H11 -> 否 | ... O11: =获奖信息!O11 -> 0.33333333
A12: =获奖信息!A12 -> 11 | B12: =获奖信息!B12 -> 45741 | C12: =获奖信息!C12 -> 生产管理科 | D12: =获奖信息!D12 -> 内部获奖 | E12: =获奖信息!E12 -> 工厂级QC发表获奖 | F12: =获奖信息!F12 -> 二等奖 | G12: =获奖信息!G12 -> 0 | H12: =获奖信息!H12 -> 否 | ... O12: =获奖信息!O12 -> 0.33333333
A13: =获奖信息!A13 -> 12 | B13: =获奖信息!B13 -> 45715 | C13: =获奖信息!C13 -> 生产管理科 | D13: =获奖信息!D13 -> 内部获奖 | E13: =获奖信息!E13 -> 工厂级QC发表获奖 | F13: =获奖信息!F13 -> 二等奖 | G13: =获奖信息!G13 -> 0 | H13: =获奖信息!H13 -> 否 | ... O13: =获奖信息!O13 -> 0.33333333
... A51: =获奖信息!A51 -> 50 | B51: =获奖信息!B51 -> 45783 | C51: =获奖信息!C51 -> 生产管理科 | D51: =获奖信息!D51 -> 内部获奖 | E51: =获奖信息!E51 -> 数字化课题开发 | F51: =获奖信息!F51 -> 重点课题 | G51: =获奖信息!G51 -> 时段生产实绩信息发布自动化 | H51: =获奖信息!H51 -> 是 | ... O51: =获奖信息!O51 -> 2.5
A52: =获奖信息!A75 -> 74 | B52: =获奖信息!B75 -> 45870 | C52: =获奖信息!C75 -> 综合管理科 | D52: =获奖信息!D75 -> 内部获奖 | E52: =获奖信息!E75 -> 数字化课题开发 | F52: =获奖信息!F75 -> 重点课题 | G52: =获奖信息!G75 -> 离职解除证明的用章申请 | H52: =获奖信息!H75 -> 是 | ... O52: =获奖信息!O75 -> 2.5
A53: =获奖信息!#REF! -> #REF! | B53: =获奖信息!#REF! -> #REF! | C53: =获奖信息!#REF! -> #REF! | D53: =获奖信息!#REF! -> #REF! | E53: =获奖信息!#REF! -> #REF! | F53: =获奖信息!#REF! -> #REF! | G53: =获奖信息!#REF! -> #REF! | H53: =获奖信息!#REF! -> #REF! | ... O53: =获奖信息!#REF! -> #REF!
A54: =获奖信息!A52 -> 51 | B54: =获奖信息!B52 -> 45821 | C54: =获奖信息!C52 -> 涂树科 | D54: =获奖信息!D52 -> 内部获奖 | E54: =获奖信息!E52 -> 改善功夫发表获奖 | F54: =获奖信息!F52 -> 一等奖 | G54: =获奖信息!G52 -> 前处理脱脂产生含油废水递减改善 | H54: =获奖信息!H52 -> 否 | ... O54: =获奖信息!O52 -> 1.5
A55: =获奖信息!A53 -> 52 | B55: =获奖信息!B53 -> 45821 | C55: =获奖信息!C53 -> 设备动力科 | D55: =获奖信息!D53 -> 内部获奖 | E55: =获奖信息!E53 -> 改善功夫发表获奖 | F55: =获奖信息!F53 -> 一等奖 | G55: =获奖信息!G53 -> 天车动作系统视觉监控系统改善 | H55: =获奖信息!H53 -> 否 | ... O55: =获奖信息!O53 -> 1.5
A56: =获奖信息!A54 -> 53 | B56: =获奖信息!B54 -> 45821 | C56: =获奖信息!C54 -> 品质保证科 | D56: =获奖信息!D54 -> 内部获奖 | E56: =获奖信息!E54 -> 改善功夫发表获奖 | F56: =获奖信息!F54 -> 二等奖 | G56: =获奖信息!G54 -> 零化AVM品质流出风险 | H56: =获奖信息!H54 -> 否 | ... O56: =获奖信息!O54 -> 1
A57: =获奖信息!A55 -> 54 | B57: =获奖信息!B55 -> 45821 | C57: =获奖信息!C55 -> 设备动力科 | D57: =获奖信息!D55 -> 内部获奖 | E57: =获奖信息!E55 -> 改善功夫发表获奖 | F57: =获奖信息!F55 -> 二等奖 | G57: =获奖信息!G55 -> 非生产时间段综合站房用电量递减 | H57: =获奖信息!H55 -> 否 | ... O57: =获奖信息!O55 -> 1
A58: =获奖信息!A56 -> 55 | B58: =获奖信息!B56 -> 45821 | C58: =获奖信息!C56 -> 冲焊科 | D58: =获奖信息!D56 -> 内部获奖 | E58: =获奖信息!E56 -> 改善功夫发表获奖 | F58: =获奖信息!F56 -> 二等奖 | G58: =获奖信息!G56 -> 焊装科稼动率提升报告 | H58: =获奖信息!H56 -> 否 | ... O58: =获奖信息!O56 -> 1
A59: =获奖信息!A57 -> 56 | B59: =获奖信息!B57 -> 45821 | C59: =获奖信息!C57 -> 大连部品科 | D59: =获奖信息!D57 -> 内部获奖 | E59: =获奖信息!E57 -> 改善功夫发表获奖 | F59: =获奖信息!F57 -> 二等奖 | G59: =获奖信息!G57 -> P32S SASH流痕改善 | H59: =获奖信息!H57 -> 否 | ... O59: =获奖信息!O57 -> 1
A60: =获奖信息!A58 -> 57 | B60: =获奖信息!B58 -> 45821 | C60: =获奖信息!C58 -> 总装科 | D60: =获奖信息!D58 -> 内部获奖 | E60: =获奖信息!E58 -> 改善功夫发表获奖 | F60: =获奖信息!F58 -> 三等奖 | G60: =获奖信息!G58 -> 零化P32S MC-R前档VIN码偏下 | H60: =获奖信息!H58 -> 否 | ... O60: =获奖信息!O58 -> 0.5
A61: =获奖信息!A59 -> 58 | B61: =获奖信息!B59 -> 45821 | C61: =获奖信息!C59 -> 设备动力科 | D61: =获奖信息!D59 -> 内部获奖 | E61: =获奖信息!E59 -> 改善功夫发表获奖 | F61: =获奖信息!F59 -> 三等奖 | G61: =获奖信息!G59 -> 树脂升降机人员挤压隐患零化 | H61: =获奖信息!H59 -> 否 | ... O61: =获奖信息!O59 -> 0.5
A62: =获奖信息!A60 -> 59 | B62: =获奖信息!B60 -> 45821 | C62: =获奖信息!C60 -> 生产管理科 | D62: =获奖信息!D60 -> 内部获奖 | E62: =获奖信息!E60 -> 改善功夫发表获奖 | F62: =获奖信息!F60 -> 三等奖 | G62: =获奖信息!G60 -> 递减无价值垃圾量 | H62: =获奖信息!H60 -> 否 | ... O62: =获奖信息!O60 -> 0.5
A63: =获奖信息!A61 -> 60 | B63: =获奖信息!B61 -> 45821 | C63: =获奖信息!C61 -> 涂树科 | D63: =获奖信息!D61 -> 内部获奖 | E63: =获奖信息!E61 -> 改善功夫发表获奖 | F63: =获奖信息!F61 -> 三等奖 | G63: =获奖信息!G61 -> 递减擦净除油作业影的喷涂DPHU | H63: =获奖信息!H61 -> 否 | ... O63: =获奖信息!O61 -> 0.5
A64: =获奖信息!A62 -> 61 | B64: =获奖信息!B62 -> 45821 | C64: =获奖信息!C62 -> 涂树科 | D64: =获奖信息!D62 -> 内部获奖 | E64: =获奖信息!E62 -> 改善功夫发表获奖 | F64: =获奖信息!F62 -> 三等奖 | G64: =获奖信息!G62 -> 递减P32S车型机盖胶泡不良件数 | H64: =获奖信息!H62 -> 否 | ... O64: =获奖信息!O62 -> 0.5
A65: =获奖信息!A63 -> 62 | B65: =获奖信息!B63 -> 45821 | C65: =获奖信息!C63 -> 冲焊科 | D65: =获奖信息!D63 -> 内部获奖 | E65: =获奖信息!E63 -> 改善功夫发表获奖 | F65: =获奖信息!F63 -> 三等奖 | G65: =获奖信息!G63 -> 提升P32S背门内板SPH | H65: =获奖信息!H63 -> 否 | ... O65: =获奖信息!O63 -> 0.5
... A67: =获奖信息!A65 -> 64 | B67: =获奖信息!B65 -> 45748 | C67: =获奖信息!C65 -> 工业工程科 | D67: =获奖信息!D65 -> 外部获奖 | E67: =获奖信息!E65 -> 全国级/DFG级奖项 | F67: =获奖信息!F65 -> 一等奖 | G67: =获奖信息!G65 -> 直接到间接-间准人员减负 | H67: =获奖信息!H65 -> 否 | ... O67: =获奖信息!O65 -> 2.5
A68: =获奖信息!A67 -> 66 | B68: =获奖信息!B67 -> 45821 | C68: =获奖信息!C67 -> 设备动力科 | D68: =获奖信息!D67 -> 外部获奖 | E68: =获奖信息!E67 -> 全国级/DFG级奖项 | F68: =获奖信息!F67 -> 二等奖 | G68: =获奖信息!G67 -> 0 | H68: =获奖信息!H67 -> 否 | ... O68: =获奖信息!O67 -> 4
A69: =获奖信息!A68 -> 67 | B69: =获奖信息!B68 -> 45809 | C69: =获奖信息!C68 -> 设备动力科 | D69: =获奖信息!D68 -> 外部获奖 | E69: =获奖信息!E68 -> DFN级/市级奖项 | F69: =获奖信息!F68 -> 二等奖 | G69: =获奖信息!G68 -> 0 | H69: =获奖信息!H68 -> 否 | ... O69: =获奖信息!O68 -> 2
A70: =获奖信息!A69 -> 68 | B70: =获奖信息!B69 -> 45809 | C70: =获奖信息!C69 -> 总装科 | D70: =获奖信息!D69 -> 外部获奖 | E70: =获奖信息!E69 -> DFN级/市级奖项 | F70: =获奖信息!F69 -> 三等奖 | G70: =获奖信息!G69 -> 0 | H70: =获奖信息!H69 -> 否 | ... O70: =获奖信息!O69 -> 1
A71: =获奖信息!#REF! -> #REF! | B71: =获奖信息!#REF! -> #REF! | C71: =获奖信息!#REF! -> #REF! | D71: =获奖信息!#REF! -> #REF! | E71: =获奖信息!#REF! -> #REF! | F71: =获奖信息!#REF! -> #REF! | G71: =获奖信息!#REF! -> #REF! | H71: =获奖信息!#REF! -> #REF! | ... O71: =获奖信息!#REF! -> #REF!
A72: =获奖信息!A71 -> 70 | B72: =获奖信息!B71 -> 45870 | C72: =获奖信息!C71 -> 冲焊科 | D72: =获奖信息!D71 -> 内部获奖 | E72: =获奖信息!E71 -> 数字化课题开发 | F72: =获奖信息!F71 -> 普通课题 | G72: =获奖信息!G71 -> 冲焊党支部员工生日提醒 | H72: =获奖信息!H71 -> 否 | ... O72: =获奖信息!O71 -> 1
A73: =获奖信息!A72 -> 71 | B73: =获奖信息!B72 -> 45870 | C73: =获奖信息!C72 -> 生产管理科 | D73: =获奖信息!D72 -> 内部获奖 | E73: =获奖信息!E72 -> 数字化课题开发 | F73: =获奖信息!F72 -> 普通课题 | G73: =获奖信息!G72 -> 工料废自动记账 | H73: =获奖信息!H72 -> 是 | ... O73: =获奖信息!O72 -> 1.5
A74: =获奖信息!A73 -> 72 | B74: =获奖信息!B73 -> 45870 | C74: =获奖信息!C73 -> 工业工程科 | D74: =获奖信息!D73 -> 内部获奖 | E74: =获奖信息!E73 -> 数字化课题开发 | F74: =获奖信息!F73 -> 普通课题 | G74: =获奖信息!G73 -> 大连工厂改善创新积分制规则答疑 | H74: =获奖信息!H73 -> 否 | ... O74: =获奖信息!O73 -> 1
A75: =获奖信息!A74 -> 73 | B75: =获奖信息!B74 -> 45870 | C75: =获奖信息!C74 -> 涂树科 | D75: =获奖信息!D74 -> 内部获奖 | E75: =获奖信息!E74 -> 数字化课题开发 | F75: =获奖信息!F74 -> 普通课题 | G75: =获奖信息!G74 -> 树脂科数字点检自动导出分析 | H75: =获奖信息!H74 -> 否 | ... O75: =获奖信息!O74 -> 1
A76: =获奖信息!#REF! -> #REF! | B76: =获奖信息!#REF! -> #REF! | C76: =获奖信息!#REF! -> #REF! | D76: =获奖信息!#REF! -> #REF! | E76: =获奖信息!#REF! -> #REF! | F76: =获奖信息!#REF! -> #REF! | G76: =获奖信息!#REF! -> #REF! | H76: =获奖信息!#REF! -> #REF! | ... O76: =获奖信息!#REF! -> #REF!
A77: =获奖信息!#REF! -> #REF! | B77: =获奖信息!#REF! -> #REF! | C77: =获奖信息!#REF! -> #REF! | D77: =获奖信息!#REF! -> #REF! | E77: =获奖信息!#REF! -> #REF! | F77: =获奖信息!#REF! -> #REF! | G77: =获奖信息!#REF! -> #REF! | H77: =获奖信息!#REF! -> #REF! | ... O77: =获奖信息!#REF! -> #REF!
A78: =获奖信息!A76 -> 75 | B78: =获奖信息!B76 -> 45870 | C78: =获奖信息!C76 -> 品质保证科 | D78: =获奖信息!D76 -> 内部获奖 | E78: =获奖信息!E76 -> 数字化课题开发 | F78: =获奖信息!F76 -> 重点课题 | G78: =获奖信息!G76 -> TQMP在线问题点自动预警 | H78: =获奖信息!H76 -> 是 | ... O78: =获奖信息!O76 -> 2.5
...

Sheet 待评估
A1: 科室 | B1: 类别 | C1: 奖项 | D1: 等级 | E1: 首次主担 | F1: 姓名 | G1: 分值
A2: 技术科 | B2: 全国级/DFG级奖项 | C2: 全国机械冶金建材行业职工技术创新成果 | D2: 二等奖 | E2: 否 | F2: 马骥 | G2: 4
A3: 工业工程科 | B3: 全国级/DFG级奖项 | C3: 全国机械冶金建材行业职工技术创新成果 | D3: 三等奖 | E3: 否 | F3: 宋伟 | G3: 3
A4: 设备动力科 | B4: 全国级/DFG级奖项 | C4: 东风最佳实践课题获奖 | D4: 综合奖项 | E4: 否 | F4: 丁友贺 | G4: 3
A5: 工业工程科 | B5: 数字化课题开发 | C5: 商品车是否订单车自动解析 | D5: 重要课题 | E5: 是 | F5: 宋伟 | G5: 2.5
A6: 涂装科 | B6: 数字化课题开发 | C6: 科室单台成本动态管控可视化 | D6: 普通课题 | E6: 是 | F6: 纪明达 | G6: 1.5
A7: 工业工程科 | B7: 数字化课题开发 | C7: 计划与实际出勤每日对比分析 | D7: 重要课题 | E7: 否 | F7: 吴广超 | G7: 2
A8: 工业工程科 | B8: 数字化课题开发 | C8: 昨日出勤差异解析自动提醒 | D8: 普通课题 | E8: 否 | F8: 吴广超 | G8: 1
A9: 工业工程科 | B9: 数字化课题开发 | C9: 工时与考勤管理看板 | D9: 重要课题 | E9: 否 | F9: 王晓冬 | G9: 2
A10: 工业工程科 | B10: 数字化课题开发 | C10: 精益工厂看板 | D10: 普通课题 | E10: 否 | F10: 王晓冬 | G10: 1
A11: 设备动力科 | B11: 数字化课题开发 | C11: 冲压模具异常处理数字化看板 | D11: 普通课题 | E11: 是 | F11: 冷洪来 | G11: 1.5
A12: 生产管理科 | B12: 数字化课题开发 | C12: 时段生产实绩信息发布自动化 | D12: 重要课题 | E12: 否 | F12: 祝益盛 | G12: 2
A13: 人事总务科 | B13: 数字化课题开发 | C13: DOA岗位异动报表自动下载且自动更新数据至报表 | D13: 重要课题 | E13: 是 | F13: 柳菁 | G13: 2.5
A16: 生产管理科 | B16: 数字化课题开发 | C16: 工料废自动过账 | D16: 普通课题 | E16: 是 | F16: 王洋 | G16: 暂未发布
A17: 人事总务科 | B17: 数字化课题开发 | C17: DOA离职报表自动下载且自动更新数据至报表 | D17: 普通课题 | E17: 否 | F17: 柳菁 | G17: 暂未发布
A18: 人事总务科 | B18: 数字化课题开发 | C18: DOA离职解除证明用章申请自动申请 | D18: 普通课题 | E18: 否 | F18: 柳菁 | G18: 暂未发布
A19: 人事总务科 | B19: 数字化课题开发 | C19: 每周制造管理部人员异动数据邮件自动回复 | D19: 普通课题 | E19: 否 | F19: 柳菁 | G19: 暂未发布
A20: 人事总务科 | B20: 数字化课题开发 | C20: 每月IE科《工厂长会议报告资料收集》邮件自动回复人力数据 | D20: 普通课题 | E20: 否 | F20: 柳菁 | G20: 暂未发布
A21: 人事总务科 | B21: 数字化课题开发 | C21: 人工成本实绩统计 | D21: 普通课题 | E21: 否 | F21: 张藜 | G21: 暂未发布

Sheet person
A1: 姓名 | B1: 科室 | C1: 总积分 | D1: 排名
A2: 宋伟 | B2: 工业工程科 | C2: 13.5 | D2: =IFERROR(_xlfn.RANK.EQ(C2,C:C,0),"并列第"&COUNTIF($D$2:D2,D2)&"位") -> 1
A3: 谢天文 | B3: 安技环保科 | C3: 10 | D3: =IFERROR(_xlfn.RANK.EQ(C3,C:C,0),"并列第"&COUNTIF($D$2:D3,D3)&"位") -> 2
A4: 吴广超 | B4: 工业工程科 | C4: 9.5 | D4: =IFERROR(_xlfn.RANK.EQ(C4,C:C,0),"并列第"&COUNTIF($D$2:D4,D4)&"位") -> 3
A5: 王瑞林 | B5: 设备动力科 | C5: 7.35 | D5: =IFERROR(_xlfn.RANK.EQ(C5,C:C,0),"并列第"&COUNTIF($D$2:D5,D5)&"位") -> 4
A6: 王晓冬 | B6: 工业工程科 | C6: 6.75 | D6: =IFERROR(_xlfn.RANK.EQ(C6,C:C,0),"并列第"&COUNTIF($D$2:D6,D6)&"位") -> 5
A7: 宋畅 | B7: 冲焊科 | C7: 6.1 | D7: =IFERROR(_xlfn.RANK.EQ(C7,C:C,0),"并列第"&COUNTIF($D$2:D7,D7)&"位") -> 6
A8: 张哲 | B8: 技术科 | C8: 6 | D8: =IFERROR(_xlfn.RANK.EQ(C8,C:C,0),"并列第"&COUNTIF($D$2:D8,D8)&"位") -> 7
A9: 柳菁 | B9: 综合管理科 | C9: 5.5 | D9: =IFERROR(_xlfn.RANK.EQ(C9,C:C,0),"并列第"&COUNTIF($D$2:D9,D9)&"位") -> 8
A10: 华运崇 | B10: 综合管理科 | C10: 5.5 | D10: =IFERROR(_xlfn.RANK.EQ(C10,C:C,0),"并列第"&COUNTIF($D$2:D10,D10)&"位") -> 8
A11: 祝益盛 | B11: 生产管理科 | C11: 4.8333333 | D11: =IFERROR(_xlfn.RANK.EQ(C11,C:C,0),"并列第"&COUNTIF($D$2:D11,D11)&"位") -> 10
A12: 于慧缘 | B12: 品质保证科 | C12: 4.8 | D12: =IFERROR(_xlfn.RANK.EQ(C12,C:C,0),"并列第"&COUNTIF($D$2:D12,D12)&"位") -> 11
A13: 康明聪 | B13: 涂树科 | C13: 4.5 | D13: =IFERROR(_xlfn.RANK.EQ(C13,C:C,0),"并列第"&COUNTIF($D$2:D13,D13)&"位") -> 12
... A44: 鲁家嫡 | B44: 品质保证科 | C44: 1.5 | D44: =IFERROR(_xlfn.RANK.EQ(C44,C:C,0),"并列第"&COUNTIF($D$2:D44,D44)&"位") -> 44
B45: 生产管理科 | C45: 0.33333333
A46: 于文书 | B46: 生产管理科 | C46: 1.8333333
A47: 王波 | B47: 技术科 | C47: 1.5
A48: 于津 | B48: 技术科 | C48: 1.5
A49: 王兴军 | B49: 品质保证科 | C49: 1.5
A50: 王玉 | B50: 涂树科 | C50: 1.5
A51: 王元成 | B51: 设备动力科 | C51: 1.5
A52: 闫瑞乾 | B52: 总装科 | C52: 1.5
A53: 李扬 | B53: 总装科 | C53: 1.5
A54: 郭旭光 | B54: 涂树科 | C54: 1.5
A55: 姚增广 | B55: 设备动力科 | C55: 1.5
A56: 曹建双 | B56: 技术科 | C56: 1.5
A57: 杨波 | B57: 冲焊科 | C57: 1.5
... A110: (空白) | B110: (空白) | C110: 0

Sheet section
A1: 科室 | B1: 总积分 | C1: 排名
A2: 设备动力科 | B2: 46.916667 | C2: =IFERROR(_xlfn.RANK.EQ(B2,B:B,0),"并列第"&COUNTIF($C$2:C2,C2)&"位") -> 1
A3: 工业工程科 | B3: 46.25 | C3: =IFERROR(_xlfn.RANK.EQ(B3,B:B,0),"并列第"&COUNTIF($C$2:C3,C3)&"位") -> 2
A4: 品质保证科 | B4: 35 | C4: =IFERROR(_xlfn.RANK.EQ(B4,B:B,0),"并列第"&COUNTIF($C$2:C4,C4)&"位") -> 3
A5: 技术科 | B5: 26.575 | C5: =IFERROR(_xlfn.RANK.EQ(B5,B:B,0),"并列第"&COUNTIF($C$2:C5,C5)&"位") -> 4
A6: 涂树科 | B6: 15.833333 | C6: =IFERROR(_xlfn.RANK.EQ(B6,B:B,0),"并列第"&COUNTIF($C$2:C6,C6)&"位") -> 5
A7: 总装科 | B7: 14.925 | C7: =IFERROR(_xlfn.RANK.EQ(B7,B:B,0),"并列第"&COUNTIF($C$2:C7,C7)&"位") -> 6
A8: 安技环保科 | B8: 14.5 | C8: =IFERROR(_xlfn.RANK.EQ(B8,B:B,0),"并列第"&COUNTIF($C$2:C8,C8)&"位") -> 7
A9: 冲焊科 | B9: 14 | C9: =IFERROR(_xlfn.RANK.EQ(B9,B:B,0),"并列第"&COUNTIF($C$2:C9,C9)&"位") -> 8
A10: 综合管理科 | B10: 14 | C10: =IFERROR(_xlfn.RANK.EQ(B10,B:B,0),"并列第"&COUNTIF($C$2:C10,C10)&"位") -> 8
A11: 生产管理科 | B11: 12.5 | C11: =IFERROR(_xlfn.RANK.EQ(B11,B:B,0),"并列第"&COUNTIF($C$2:C11,C11)&"位") -> 10
A12: 大连财务科 | B12: 2.5 | C12: =IFERROR(_xlfn.RANK.EQ(B12,B:B,0),"并列第"&COUNTIF($C$2:C12,C12)&"位") -> 11
A13: 党群工作室 | B13: 1.5 | C13: =IFERROR(_xlfn.RANK.EQ(B13,B:B,0),"并列第"&COUNTIF($C$2:C13,C13)&"位") -> 12
A14: 大连部品科 | B14: 1 | C14: =IFERROR(_xlfn.RANK.EQ(B14,B:B,0),"并列第"&COUNTIF($C$2:C14,C14)&"位") -> 13
A15: (空白) | B15: 0

Sheet 积分标准
A1: 获奖途径 | B1: 所获奖项分类 | C1: 所获奖项级别 | D1: 分数
A2: 外部获奖 | B2: 全球级/联盟级奖项 | C2: 一等奖 | D2: 6 | G2: {=IFERROR(_xlfn.UNIQUE(_xlfn._xlws.FILTER(B:B, A:A=D2)), "")} | H2: {=IFERROR(INDEX($B$2:$B$100, MATCH(0, COUNTIFS($H$2:H2, $B$2:$B$100, $A$2:$A$100, D3), 0)), "")}
A3: 外部获奖 | B3: 全球级/联盟级奖项 | C3: 二等奖 | D3: 5 | G3: {=IFERROR(_xlfn.UNIQUE(_xlfn._xlws.FILTER(B:B, A:A=D3)), "")}
A4: 外部获奖 | B4: 全球级/联盟级奖项 | C4: 三等奖 | D4: 4 | G4: {=IFERROR(_xlfn.UNIQUE(_xlfn._xlws.FILTER(B:B, A:A=D4)), "")}
A5: 外部获奖 | B5: 全球级/联盟级奖项 | C5: 综合奖项 | D5: 4 | G5: {=IFERROR(_xlfn.UNIQUE(_xlfn._xlws.FILTER(B:B, A:A=D5)), "")}
A6: 外部获奖 | B6: 全国级/DFG级奖项 | C6: 一等奖 | D6: 5 | G6: {=IFERROR(_xlfn.UNIQUE(_xlfn._xlws.FILTER(B:B, A:A=D6)), "")}
A7: 外部获奖 | B7: 全国级/DFG级奖项 | C7: 二等奖 | D7: 4 | G7: {=IFERROR(_xlfn.UNIQUE(_xlfn._xlws.FILTER(B:B, A:A=D7)), "")}
A8: 外部获奖 | B8: 全国级/DFG级奖项 | C8: 三等奖 | D8: 3 | G8: {=IFERROR(_xlfn.UNIQUE(_xlfn._xlws.FILTER(B:B, A:A=D8)), "")}
A9: 外部获奖 | B9: 全国级/DFG级奖项 | C9: 综合奖项 | D9: 3 | G9: {=IFERROR(_xlfn.UNIQUE(_xlfn._xlws.FILTER(B:B, A:A=D9)), "")}
A10: 外部获奖 | B10: 区域级/省级奖项 | C10: 一等奖 | D10: 4 | G10: {=IFERROR(_xlfn.UNIQUE(_xlfn._xlws.FILTER(B:B, A:A=D10)), "")}
A11: 外部获奖 | B11: 区域级/省级奖项 | C11: 二等奖 | D11: 3 | G11: {=IFERROR(_xlfn.UNIQUE(_xlfn._xlws.FILTER(B:B, A:A=D11)), "")}
A12: 外部获奖 | B12: 区域级/省级奖项 | C12: 三等奖 | D12: 2 | G12: {=IFERROR(_xlfn.UNIQUE(_xlfn._xlws.FILTER(B:B, A:A=D12)), "")}
A13: 外部获奖 | B13: 区域级/省级奖项 | C13: 综合奖项 | D13: 2 | G13: {=IFERROR(_xlfn.UNIQUE(_xlfn._xlws.FILTER(B:B, A:A=D13)), "")}
A14: 外部获奖 | B14: DFN级/市级奖项 | C14: 一等奖 | D14: 3 | G14: {=IFERROR(_xlfn.UNIQUE(_xlfn._xlws.FILTER(B:B, A:A=D14)), "")}
... A23: 内部获奖 | B23: 工厂级QC发表获奖 | C23: 三等奖 | D23: 1.5 | G23: {=IFERROR(_xlfn.UNIQUE(_xlfn._xlws.FILTER(B:B, A:A=D23)), "")}
A24: 内部获奖 | B24: 改善功夫发表获奖 | C24: 一等奖 | D24: 1.5
A25: 内部获奖 | B25: 改善功夫发表获奖 | C25: 二等奖 | D25: 1
A26: 内部获奖 | B26: 改善功夫发表获奖 | C26: 三等奖 | D26: 0.5
A27: 内部获奖 | B27: 创享慧提案被外部门采纳 | C27: 一等奖 | D27: 0.5
A28: 内部获奖 | B28: Top摘牌课题完成 | C28: 一等奖 | D28: 2
A29: 内部获奖 | B29: 数字化课题开发 | C29: 重点课题 | D29: 2
A30: 内部获奖 | B30: 数字化课题开发 | C30: 普通课题 | D30: 1

Sheet 规则说明
A1: 外部获奖 | H1: 内部获奖
A2: 加分项目 | B2: 加分值 | H2: 加分项目 | I2: 加分值
B3: 一等奖 | C3: 二等奖 | D3: 三等奖 | E3: 综合奖项 | I3: 一等奖 | J3: 二等奖 | K3: 三等奖
A4: 全球级/联盟级奖项 | B4: 6 | C4: 5 | D4: 4 | E4: 4 | H4: 工厂级QC发表获奖 | I4: 2.5 | J4: 2 | K4: 1.5
A5: 全国级/DFG级奖项 | B5: 5 | C5: 4 | D5: 3 | E5: 3 | H5: 改善功夫发表获奖 | I5: 1.5 | J5: 1 | K5: 0.5
A6: 区域级/省级奖项 | B6: 4 | C6: 3 | D6: 2 | E6: 2 | H6: 创享慧提案被外部门采纳 | I6: 0.5
A7: DFN级/市级奖项 | B7: 3 | C7: 2 | D7: 1 | E7: 1 | H7: Top摘牌课题完成 | I7: 2
A8: 国家专利受理 | B8: 发明专利+4 | C8: 实用新型+3 | D8: 外观设计+2 | H8: 数字化课题完成 | I8: 重要课题+2 | J8: 普通课题+1

Sheet personV1
A1: Name | B1: Section | C1: ‌Total Score | D1: Rank
A2: =person!A2 -> 宋伟 | B2: =person!B2 -> 工业工程科 | C2: =person!C2 -> 13.5 | D2: =person!D2 -> 1
A3: =person!A3 -> 谢天文 | B3: =person!B3 -> 安技环保科 | C3: =person!C3 -> 10 | D3: =person!D3 -> 2
A4: =person!A4 -> 吴广超 | B4: =person!B4 -> 工业工程科 | C4: =person!C4 -> 9.5 | D4: =person!D4 -> 3
A5: =person!A5 -> 王瑞林 | B5: =person!B5 -> 设备动力科 | C5: =person!C5 -> 7.35 | D5: =person!D5 -> 4
A6: =person!A6 -> 王晓冬 | B6: =person!B6 -> 工业工程科 | C6: =person!C6 -> 6.75 | D6: =person!D6 -> 5
A7: =person!A7 -> 宋畅 | B7: =person!B7 -> 冲焊科 | C7: =person!C7 -> 6.1 | D7: =person!D7 -> 6
A8: =person!A8 -> 张哲 | B8: =person!B8 -> 技术科 | C8: =person!C8 -> 6 | D8: =person!D8 -> 7
A9: =person!A9 -> 柳菁 | B9: =person!B9 -> 综合管理科 | C9: =person!C9 -> 5.5 | D9: =person!D9 -> 8
A10: =person!A10 -> 华运崇 | B10: =person!B10 -> 综合管理科 | C10: =person!C10 -> 5.5 | D10: =person!D10 -> 8
A11: =person!A11 -> 祝益盛 | B11: =person!B11 -> 生产管理科 | C11: =person!C11 -> 4.8333333 | D11: =person!D11 -> 10
A12: =person!A12 -> 于慧缘 | B12: =person!B12 -> 品质保证科 | C12: =person!C12 -> 4.8 | D12: =person!D12 -> 11
A13: =person!A13 -> 康明聪 | B13: =person!B13 -> 涂树科 | C13: =person!C13 -> 4.5 | D13: =person!D13 -> 12
... A21: =person!A21 -> 刘昇 | B21: =person!B21 -> 设备动力科 | C21: =person!C21 -> 4 | D21: =person!D21 -> 17

Sheet sectionV1
A1: Section | B1: ‌Total Score | C1: Rank
A2: =section!A2 -> 设备动力科 | B2: =section!B2 -> 46.916667 | C2: =section!C2 -> 1
A3: =section!A3 -> 工业工程科 | B3: =section!B3 -> 46.25 | C3: =section!C3 -> 2
A4: =section!A4 -> 品质保证科 | B4: =section!B4 -> 35 | C4: =section!C4 -> 3
A5: =section!A5 -> 技术科 | B5: =section!B5 -> 26.575 | C5: =section!C5 -> 4
A6: =section!A6 -> 涂树科 | B6: =section!B6 -> 15.833333 | C6: =section!C6 -> 5
A7: =section!A7 -> 总装科 | B7: =section!B7 -> 14.925 | C7: =section!C7 -> 6
A8: =section!A8 -> 安技环保科 | B8: =section!B8 -> 14.5 | C8: =section!C8 -> 7
A9: =section!A9 -> 冲焊科 | B9: =section!B9 -> 14 | C9: =section!C9 -> 8
A10: =section!A10 -> 综合管理科 | B10: =section!B10 -> 14 | C10: =section!C10 -> 8
A11: =section!A11 -> 生产管理科 | B11: =section!B11 -> 12.5 | C11: =section!C11 -> 10
A12: =section!A12 -> 大连财务科 | B12: =section!B12 -> 2.5 | C12: =section!C12 -> 11
A13: =section!A13 -> 党群工作室 | B13: =section!B13 -> 1.5 | C13: =section!C13 -> 12
... A15: =section!A15 -> (空白) | B15: =section!B15 -> 0 | C15: =section!C15 -> 0
